Workbook

Sheet Panels
A1: PANEL_ID | B1: ERA_ID | C1: BECKENSALL_ID | D1: VERSION | E1: PANEL_NAME | F1: PANEL_NUMBER | G1: IS_PUBLIC | H1: UPDATED_BY | I1: UPDATED | J1: ARCHIVE_FOLDER
A2: 730 | B2: 730 | C2: 240 | D2: 1 | E2: Amerside Law | F2: 3a | G2: 1 | H2: 0 | J2: 836
A3: 731 | B3: 731 | C3: 360 | D3: 1 | E3: Beadnell Caravan Park | G3: 1 | H3: 0 | J3: 836
A4: 732 | B4: 732 | C4: 361 | D4: 1 | E4: North Sunderland, Seahouses | G4: 1 | H4: 0 | J4: 836
A5: 733 | B5: 733 | C5: 355 | D5: 1 | E5: Turf Knowe | F5: a | G5: 1 | H5: 0 | J5: 836
A6: 734 | B6: 734 | C6: 721 | D6: 1 | E6: West Park Camp, Birtley | G6: 1 | H6: 0 | J6: 836
A7: 735 | B7: 735 | C7: 722 | D7: 1 | E7: Carry House Camp, Birtley | G7: 1 | H7: 0 | J7: 836
A8: 736 | B8: 736 | C8: 732 | D8: 1 | E8: Gunner Peak Camp, Barrasford | F8: a | G8: 1 | H8: 0 | J8: 836
A9: 737 | B9: 737 | C9: 733 | D9: 1 | E9: Gunner Peak Camp, Barrasford | F9: b | G9: 1 | H9: 0 | J9: 836
A10: 738 | B10: 738 | C10: 734 | D10: 1 | E10: Blue Crag, Colwell | F10: a | G10: 1 | H10: 0 | J10: 836
A11: 739 | B11: 739 | C11: 735 | D11: 1 | E11: Blue Crag, Colwell | F11: b | G11: 1 | H11: 0 | J11: 836
A12: 740 | B12: 740 | C12: 741 | D12: 1 | E12: Homers Lane, Warden | G12: 1 | H12: 0 | J12: 836
A13: 741 | B13: 741 | C13: 693 | D13: 1 | E13: Houxty Cottage | G13: 1 | H13: 0 | J13: 836
A14: 742 | B14: 742 | C14: 742 | D14: 1 | E14: Hartleyburn Common | F14: 1a | G14: 1 | H14: 0 | J14: 836
A15: 743 | B15: 743 | C15: 743 | D15: 1 | E15: Hartleyburn Common | F15: 1b | G15: 1 | H15: 0 | J15: 836
A16: 744 | B16: 744 | C16: 744 | D16: 1 | E16: Hartleyburn Common | F16: 1c | G16: 1 | H16: 0 | J16: 836
A17: 745 | B17: 745 | C17: 745 | D17: 1 | E17: Hartleyburn Common | F17: 1d | G17: 1 | H17: 0 | J17: 836
A18: 746 | B18: 746 | C18: 746 | D18: 1 | E18: Hartleyburn Common | F18: 1e | G18: 1 | H18: 0 | J18: 836
A19: 747 | B19: 747 | C19: 747 | D19: 1 | E19: Hartleyburn Common | F19: 2 | G19: 1 | H19: 0 | J19: 836
A20: 748 | B20: 748 | C20: 748 | D20: 1 | E20: Hartleyburn Common | F20: 3 | G20: 1 | H20: 0 | J20: 836
A21: 749 | B21: 749 | C21: 0 | D21: 1 | E21: Hartleyburn Common | F21: 5 | G21: 1 | H21: 0 | J21: 836
A22: 750 | B22: 750 | C22: 750 | D22: 1 | E22: Prudhoe Castle | G22: 1 | H22: 0 | J22: 836
A23: 751 | B23: 751 | C23: 796 | D23: 1 | E23: High Shaw Farm | G23: 1 | H23: 0 | J23: 836
A24: 752 | B24: 752 | C24: 752 | D24: 1 | E24: Chesters Roman Site | F24: a | G24: 1 | H24: 0 | J24: 836
A25: 753 | B25: 753 | C25: 800 | D25: 1 | E25: Holy Island | F25: a | G25: 1 | H25: 0 | J25: 836
A26: 754 | B26: 754 | C26: 801 | D26: 1 | E26: Holy Island | F26: b | G26: 1 | H26: 0 | J26: 836
A27: 755 | B27: 755 | C27: 837 | D27: 1 | E27: Fowberry Excavation Site Kerbstone | F27: 1 | G27: 1 | H27: 0 | J27: 836
A28: 756 | B28: 756 | C28: 838 | D28: 1 | E28: Fowberry Excavation Site Kerbstone | F28: 2 | G28: 1 | H28: 0 | J28: 836
A29: 757 | B29: 757 | C29: 839 | D29: 1 | E29: Fowberry Excavation Site Kerbstone | F29: 3 | G29: 1 | H29: 0 | J29: 836
A30: 758 | B30: 758 | C30: 840 | D30: 1 | E30: Fowberry Excavation Site Kerbstone | F30: 4 | G30: 1 | H30: 0 | J30: 836
A31: 759 | B31: 759 | C31: 1050 | D31: 1 | E31: West Horton 6 Portable | F31: c | G31: 1 | H31: 0 | J31: 836
A32: 760 | B32: 760 | C32: 1062 | D32: 1 | E32: Weetwood Cairn | F32: e | G32: 1 | H32: 0 | J32: 836
A33: 761 | B33: 761 | C33: 1074 | D33: 1 | E33: Weetwood Cairn | F33: q | G33: 1 | H33: 0 | J33: 836
A34: 762 | B34: 762 | C34: 1076 | D34: 1 | E34: Weetwood Cairn | F34: s | G34: 1 | H34: 0 | J34: 836
A35: 763 | B35: 763 | C35: 1080 | D35: 1 | E35: Weetwood Cairn | F35: x | G35: 1 | H35: 0 | J35: 836
A36: 764 | B36: 764 | C36: 1089 | D36: 1 | E36: Weetwood Cairn | F36: gg | G36: 1 | H36: 0 | J36: 836
A37: 765 | B37: 765 | C37: 1094 | D37: 1 | E37: Weetwood Cairn | F37: jj | G37: 1 | H37: 0 | J37: 836
A38: 766 | B38: 766 | C38: 1101 | D38: 1 | E38: Weetwood Cairn Kerbstone | G38: 1 | H38: 0 | J38: 836
A39: 767 | B39: 767 | C39: 1121 | D39: 1 | E39: The Ringses | F39: 6c | G39: 1 | H39: 0 | J39: 836
A40: 768 | B40: 768 | C40: 1137 | D40: 1 | E40: Throckley Bank Portable | G40: 1 | H40: 0 | J40: 836
...

Sheet Motifs
A1: PANEL_ID | B1: MOTIF_TYPE_ID | C1: VALUE | D1: Motif | E1: Location
A2: 1 | B2: 52 | C2: 5 | D2: =VLOOKUP(B2,ERA_MOTIF_TYPES.csv!$A$1:$C$119,2,1) -> Single or multiple cups | E2: =VLOOKUP(A2,Panels!$A$1:$E$2104,5,0) -> Ord
A3: 1 | B3: 66 | C3: 1 | D3: =VLOOKUP(B3,ERA_MOTIF_TYPES.csv!$A$1:$C$119,2,1) -> Cup and groove with multiple penannulars | E3: =VLOOKUP(A3,Panels!$A$1:$E$2104,5,0) -> Ord
A4: 3 | B4: 52 | C4: 1 | D4: =VLOOKUP(B4,ERA_MOTIF_TYPES.csv!$A$1:$C$119,2,1) -> Single or multiple cups | E4: =VLOOKUP(A4,Panels!$A$1:$E$2104,5,0) -> Ord
A5: 4 | B5: 52 | C5: 3 | D5: =VLOOKUP(B5,ERA_MOTIF_TYPES.csv!$A$1:$C$119,2,1) -> Single or multiple cups | E5: =VLOOKUP(A5,Panels!$A$1:$E$2104,5,0) -> The Duddo Stones
A6: 5 | B6: 2 | C6: 1 | D6: =VLOOKUP(B6,ERA_MOTIF_TYPES.csv!$A$1:$C$119,2,1) -> Random Cluster | E6: =VLOOKUP(A6,Panels!$A$1:$E$2104,5,0) -> Broomridge
A7: 5 | B7: 12 | C7: 2 | D7: =VLOOKUP(B7,ERA_MOTIF_TYPES.csv!$A$1:$C$119,2,1) -> Multi Arc | E7: =VLOOKUP(A7,Panels!$A$1:$E$2104,5,0) -> Broomridge
A8: 5 | B8: 13 | C8: 1 | D8: =VLOOKUP(B8,ERA_MOTIF_TYPES.csv!$A$1:$C$119,2,1) -> Single Ring + cup | E8: =VLOOKUP(A8,Panels!$A$1:$E$2104,5,0) -> Broomridge
A9: 5 | B9: 14 | C9: 5 | D9: =VLOOKUP(B9,ERA_MOTIF_TYPES.csv!$A$1:$C$119,2,1) -> Multi Ring + cup | E9: =VLOOKUP(A9,Panels!$A$1:$E$2104,5,0) -> Broomridge
A10: 5 | B10: 16 | C10: 1 | D10: =VLOOKUP(B10,ERA_MOTIF_TYPES.csv!$A$1:$C$119,2,1) -> Single Arc + cup | E10: =VLOOKUP(A10,Panels!$A$1:$E$2104,5,0) -> Broomridge
A11: 5 | B11: 31 | C11: 1 | D11: =VLOOKUP(B11,ERA_MOTIF_TYPES.csv!$A$1:$C$119,2,1) -> Cup and Groove | E11: =VLOOKUP(A11,Panels!$A$1:$E$2104,5,0) -> Broomridge
A12: 5 | B12: 36 | C12: 1 | D12: =VLOOKUP(B12,ERA_MOTIF_TYPES.csv!$A$1:$C$119,2,1) -> Cup Groove and arc | E12: =VLOOKUP(A12,Panels!$A$1:$E$2104,5,0) -> Broomridge
A13: 5 | B13: 52 | C13: 12 | D13: =VLOOKUP(B13,ERA_MOTIF_TYPES.csv!$A$1:$C$119,2,1) -> Single or multiple cups | E13: =VLOOKUP(A13,Panels!$A$1:$E$2104,5,0) -> Broomridge
... A4710: 2252 | B4710: 1 | C4710: 9 | D4710: =VLOOKUP(B4710,ERA_MOTIF_TYPES.csv!$A$1:$C$119,2,1) -> Cups Single | E4710: =VLOOKUP(A4710,Panels!$A$1:$E$2104,5,0) -> Woodhouse Crag
A4711: 2253 | B4711: 13 | D4711: =VLOOKUP(B4711,ERA_MOTIF_TYPES.csv!$A$1:$C$119,2,1) -> Single Ring + cup | E4711: =VLOOKUP(A4711,Panels!$A$1:$E$2104,5,0) -> Woodhouse Crag
A4712: 2253 | B4712: 16 | C4712: 2 | D4712: =VLOOKUP(B4712,ERA_MOTIF_TYPES.csv!$A$1:$C$119,2,1) -> Single Arc + cup | E4712: =VLOOKUP(A4712,Panels!$A$1:$E$2104,5,0) -> Woodhouse Crag
A4713: 2254 | B4713: 1 | C4713: 5 | D4713: =VLOOKUP(B4713,ERA_MOTIF_TYPES.csv!$A$1:$C$119,2,1) -> Cups Single | E4713: =VLOOKUP(A4713,Panels!$A$1:$E$2104,5,0) -> High Crag
A4714: 2254 | B4714: 16 | C4714: 1 | D4714: =VLOOKUP(B4714,ERA_MOTIF_TYPES.csv!$A$1:$C$119,2,1) -> Single Arc + cup | E4714: =VLOOKUP(A4714,Panels!$A$1:$E$2104,5,0) -> High Crag
A4715: 2255 | B4715: 1 | C4715: 21 | D4715: =VLOOKUP(B4715,ERA_MOTIF_TYPES.csv!$A$1:$C$119,2,1) -> Cups Single | E4715: =VLOOKUP(A4715,Panels!$A$1:$E$2104,5,0) -> Piper's Crag
A4716: 2255 | B4716: 13 | C4716: 1 | D4716: =VLOOKUP(B4716,ERA_MOTIF_TYPES.csv!$A$1:$C$119,2,1) -> Single Ring + cup | E4716: =VLOOKUP(A4716,Panels!$A$1:$E$2104,5,0) -> Piper's Crag
A4717: 2255 | B4717: 14 | C4717: 1 | D4717: =VLOOKUP(B4717,ERA_MOTIF_TYPES.csv!$A$1:$C$119,2,1) -> Multi Ring + cup | E4717: =VLOOKUP(A4717,Panels!$A$1:$E$2104,5,0) -> Piper's Crag
A4718: 2255 | B4718: 16 | C4718: 6 | D4718: =VLOOKUP(B4718,ERA_MOTIF_TYPES.csv!$A$1:$C$119,2,1) -> Single Arc + cup | E4718: =VLOOKUP(A4718,Panels!$A$1:$E$2104,5,0) -> Piper's Crag
A4719: 2255 | B4719: 25 | C4719: 3 | D4719: =VLOOKUP(B4719,ERA_MOTIF_TYPES.csv!$A$1:$C$119,2,1) -> Linear | E4719: =VLOOKUP(A4719,Panels!$A$1:$E$2104,5,0) -> Piper's Crag
A4720: 2255 | B4720: 33 | C4720: 1 | D4720: =VLOOKUP(B4720,ERA_MOTIF_TYPES.csv!$A$1:$C$119,2,1) -> Cup Groove and multi ring | E4720: =VLOOKUP(A4720,Panels!$A$1:$E$2104,5,0) -> Piper's Crag
A4721: 2256 | B4721: 1 | C4721: 1 | D4721: =VLOOKUP(B4721,ERA_MOTIF_TYPES.csv!$A$1:$C$119,2,1) -> Cups Single | E4721: =VLOOKUP(A4721,Panels!$A$1:$E$2104,5,0) -> Piper's Crag
A4722: 2257 | B4722: 1 | C4722: 2 | D4722: =VLOOKUP(B4722,ERA_MOTIF_TYPES.csv!$A$1:$C$119,2,1) -> Cups Single | E4722: =VLOOKUP(A4722,Panels!$A$1:$E$2104,5,0) -> Piper's Crag
A4723: 2258 | B4723: 13 | C4723: 1 | D4723: =VLOOKUP(B4723,ERA_MOTIF_TYPES.csv!$A$1:$C$119,2,1) -> Single Ring + cup | E4723: =VLOOKUP(A4723,Panels!$A$1:$E$2104,5,0) -> Piper's Crag
... A4762: 2286 | B4762: 13 | C4762: 1 | D4762: =VLOOKUP(B4762,ERA_MOTIF_TYPES.csv!$A$1:$C$119,2,1) -> Single Ring + cup | E4762: =VLOOKUP(A4762,Panels!$A$1:$E$2104,5,0) -> Rough Holden
A4763: 2286 | B4763: 17 | D4763: =VLOOKUP(B4763,ERA_MOTIF_TYPES.csv!$A$1:$C$119,2,1) -> Single Penannular + cup | E4763: =VLOOKUP(A4763,Panels!$A$1:$E$2104,5,0) -> Rough Holden
A4764: 2286 | B4764: 25 | C4764: 2 | D4764: =VLOOKUP(B4764,ERA_MOTIF_TYPES.csv!$A$1:$C$119,2,1) -> Linear | E4764: =VLOOKUP(A4764,Panels!$A$1:$E$2104,5,0) -> Rough Holden
A4765: 2286 | B4765: 31 | C4765: 1 | D4765: =VLOOKUP(B4765,ERA_MOTIF_TYPES.csv!$A$1:$C$119,2,1) -> Cup and Groove | E4765: =VLOOKUP(A4765,Panels!$A$1:$E$2104,5,0) -> Rough Holden
A4766: 2286 | B4766: 117 | C4766: 1 | D4766: =VLOOKUP(B4766,ERA_MOTIF_TYPES.csv!$A$1:$C$119,2,1) -> Dumb-bell | E4766: =VLOOKUP(A4766,Panels!$A$1:$E$2104,5,0) -> Rough Holden
A4767: 2287 | B4767: 1 | C4767: 14 | D4767: =VLOOKUP(B4767,ERA_MOTIF_TYPES.csv!$A$1:$C$119,2,1) -> Cups Single | E4767: =VLOOKUP(A4767,Panels!$A$1:$E$2104,5,0) -> Rough Holden
A4768: 2287 | B4768: 25 | C4768: 3 | D4768: =VLOOKUP(B4768,ERA_MOTIF_TYPES.csv!$A$1:$C$119,2,1) -> Linear | E4768: =VLOOKUP(A4768,Panels!$A$1:$E$2104,5,0) -> Rough Holden
A4769: 2287 | B4769: 31 | C4769: 2 | D4769: =VLOOKUP(B4769,ERA_MOTIF_TYPES.csv!$A$1:$C$119,2,1) -> Cup and Groove | E4769: =VLOOKUP(A4769,Panels!$A$1:$E$2104,5,0) -> Rough Holden
A4770: 2288 | B4770: 1 | C4770: 3 | D4770: =VLOOKUP(B4770,ERA_MOTIF_TYPES.csv!$A$1:$C$119,2,1) -> Cups Single | E4770: =VLOOKUP(A4770,Panels!$A$1:$E$2104,5,0) -> Rough Holden
A4771: 2289 | B4771: 1 | C4771: 13 | D4771: =VLOOKUP(B4771,ERA_MOTIF_TYPES.csv!$A$1:$C$119,2,1) -> Cups Single | E4771: =VLOOKUP(A4771,Panels!$A$1:$E$2104,5,0) -> Robin Hood Wood
A4772: 2289 | B4772: 25 | C4772: 1 | D4772: =VLOOKUP(B4772,ERA_MOTIF_TYPES.csv!$A$1:$C$119,2,1) -> Linear | E4772: =VLOOKUP(A4772,Panels!$A$1:$E$2104,5,0) -> Robin Hood Wood
A4773: 2289 | B4773: 117 | C4773: 1 | D4773: =VLOOKUP(B4773,ERA_MOTIF_TYPES.csv!$A$1:$C$119,2,1) -> Dumb-bell | E4773: =VLOOKUP(A4773,Panels!$A$1:$E$2104,5,0) -> Robin Hood Wood
A4774: 2290 | B4774: 1 | C4774: 3 | D4774: =VLOOKUP(B4774,ERA_MOTIF_TYPES.csv!$A$1:$C$119,2,1) -> Cups Single | E4774: =VLOOKUP(A4774,Panels!$A$1:$E$2104,5,0) -> Robin Hood Wood
...

Sheet Pivot Table 1

Sheet ERA_MOTIF_TYPES.csv
A1: MOTIF_TYPE_ID | B1: NAME | C1: DESCRIPTION | D1: BECKENSALL_ID | E1: BECKENSALL_ORDER
A2: 1 | B2: Cups Single
A3: 2 | B3: Random Cluster | C3: ERA Motif Type
A4: 3 | B4: Parallel Domino | C4: ERA Motif Type
A5: 4 | B5: Counter-sunk | C5: ERA Motif Type
A6: 5 | B6: Rosette | C6: ERA Motif Type
A7: 6 | B7: curved or straight line | C7: ERA Motif Type
A8: 7 | B8: Single Ring | C8: ERA Motif Type
A9: 8 | B9: Multi Ring | C9: ERA Motif Type
A10: 9 | B10: Multi Penanular | C10: ERA Motif Type
A11: 10 | B11: Single Arc | C11: ERA Motif Type
A12: 11 | B12: Single Penannular | C12: ERA Motif Type
A13: 12 | B13: Multi Arc | C13: ERA Motif Type
A14: 13 | B14: Single Ring + cup | C14: ERA Motif Type
... A52: 51 | B52: Bowls | C52: ERA Motif Type
A53: 52 | B53: Single or multiple cups | C53: Beckensall Motif Type | D53: 1 | E53: 2
A54: 53 | B54: Domino patterns and parallel lines | C54: Beckensall Motif Type | D54: 3 | E54: 4
A55: 54 | B55: Rosette | C55: Beckensall Motif Type | D55: 4 | E55: 5
A56: 55 | B56: Cups in a straight or curved line | C56: Beckensall Motif Type | D56: 5 | E56: 6
A57: 56 | B57: Cups countersunk | C57: Beckensall Motif Type | D57: 6 | E57: 9
A58: 57 | B58: Cup and ring | C58: Beckensall Motif Type | D58: 7 | E58: 1
A59: 58 | B59: Cup and multiple rings | C59: Beckensall Motif Type | D59: 8 | E59: 2
A60: 59 | B60: Cup and penannular | C60: Beckensall Motif Type | D60: 9 | E60: 3
A61: 60 | B61: Cup and multiple penannulars | C61: Beckensall Motif Type | D61: 10 | E61: 4
A62: 61 | B62: Cup and arc (or semi-ovoid) | C62: Beckensall Motif Type | D62: 11 | E62: 5
A63: 62 | B63: Cup and multiple arcs | C63: Beckensall Motif Type | D63: 12 | E63: 6
A64: 63 | B64: Cup with groove cutting through ring | C64: Beckensall Motif Type | D64: 13 | E64: 3
... A117: 116 | B117: Multiple square grooves | C117: Beckensall Motif Type | D117: 66 | E117: 10
A118: 117 | B118: Dumb-bell | C118: ERA Motif Type
A119: 118 | B119: Random peck marks | C119: ERA Motif Type
